import { render, screen, fireEvent } from '@testing-library/react';
import { vi, beforeAll, afterAll, describe, it, expect } from 'vitest';
import ErrorBoundary from './ErrorBoundary';

// Mock component that throws an error
const ThrowError = ({ shouldThrow }: { shouldThrow: boolean }) => {
  if (shouldThrow) {
    throw new Error('Test error');
  }
  return <div>No error</div>;
};

// Mock console.error to avoid noise in tests
const originalError = console.error;
beforeAll(() => {
  console.error = vi.fn();
});

afterAll(() => {
  console.error = originalError;
});

describe('ErrorBoundary', () => {
  it('renders children when there is no error', () => {
    render(
      <ErrorBoundary>
        <ThrowError shouldThrow={false} />
      </ErrorBoundary>
    );

    expect(screen.getByText('No error')).toBeInTheDocument();
  });

  it('renders error UI when there is an error', () => {
    render(
      <ErrorBoundary>
        <ThrowError shouldThrow={true} />
      </ErrorBoundary>
    );

    expect(screen.getByText('Something went wrong')).toBeInTheDocument();
    expect(screen.getByText(/We're sorry, but something unexpected happened/)).toBeInTheDocument();
  });

  it('renders custom fallback when provided', () => {
    const customFallback = <div>Custom error message</div>;
    
    render(
      <ErrorBoundary fallback={customFallback}>
        <ThrowError shouldThrow={true} />
      </ErrorBoundary>
    );

    expect(screen.getByText('Custom error message')).toBeInTheDocument();
  });

  it('calls onError callback when error occurs', () => {
    const onError = vi.fn();
    
    render(
      <ErrorBoundary onError={onError}>
        <ThrowError shouldThrow={true} />
      </ErrorBoundary>
    );

    expect(onError).toHaveBeenCalledWith(
      expect.any(Error),
      expect.objectContaining({
        componentStack: expect.any(String)
      })
    );
  });

  it('allows retry functionality', () => {
    const { container } = render(
      <ErrorBoundary>
        <ThrowError shouldThrow={true} />
      </ErrorBoundary>
    );

    // Check that error UI is displayed
    expect(container.querySelector('h2')).toHaveTextContent('Something went wrong');

    const retryButton = container.querySelector('button');
    expect(retryButton).toHaveTextContent('Try Again');
    
    // Verify retry button is clickable (doesn't throw error)
    expect(() => fireEvent.click(retryButton!)).not.toThrow();
  });

  it('shows error details in development mode', () => {
    const originalEnv = process.env.NODE_ENV;
    process.env.NODE_ENV = 'development';

    render(
      <ErrorBoundary>
        <ThrowError shouldThrow={true} />
      </ErrorBoundary>
    );

    expect(screen.getByText('Error Details (Development)')).toBeInTheDocument();

    process.env.NODE_ENV = originalEnv;
  });
});